Workbook

Sheet Project List 2026
A1: Project name | B1: Project name (as in ITS1) | C1: Tower | D1: PC Ownership | E1: PM name | F1: Internal/ External | G1: SalesForce Proposal # / BCA # | H1: #BSO/IO | I1: Project status | J1: Start date | K1: End date | L1: BU | M1: Value 2026 | N1: Probability [%] | O1: Value weighted 2026 | P1: Comments
A2: BARN Security Enforcement | B2: LAN CONNECTIVITY | C2: Telecoms | D2: Others | E2: Alina Nosulych | F2: Internal | G2: n/a | H2: 89100298 | I2: Ongoing | J2: 46068 | K2: 46265 | L2: ITS | M2: 0 | N2: 1 | O2: =M2*N2 -> 0 | P2: Alina Nosulych for 10MD (%MDs per m onth), allocation only, RUN order
A3: F5 Refresh | B3: F5 BIG-IP EOSL Refresh - GLOBAL | C3: Telecoms | D3: Telecoms | E3: Alina Nosulych | F3: Internal | G3: n/a | H3: 87101386 | I3: Ongoing | J3: 46023 | K3: 46387 | L3: ITS | M3: 0 | N3: 1 | O3: =M3*N3 -> 0 | P3: 40% PM allocation
A4: ACI Upgrade - global activitiy (BARN related) | B4: ACI Upgrade - global activitiy (BARN related) | C4: Telecoms | D4: Telecoms | E4: Alina Nosulych | F4: Internal | G4: n/a | H4: 89100298 | I4: Completed | J4: 46068 | K4: 46142 | L4: ITS | M4: 0 | N4: 1 | O4: =M4*N4 -> 0 | P4: To be paid by RUN order, allocation only
A5: Central FAX migration to eFAX solution | B5: Central FAX migration to eFAX | C5: Telecoms | D5: Telecoms | E5: Alina Nosulych | F5: Internal | G5: n/a | H5: 89100536 | I5: Completed | J5: 46023 | K5: 46203 | L5: Multiple | M5: 0 | N5: 1 | O5: =M5*N5 -> 0 | P5: PM 20% allocation
A6: NGFW Proposals EXP | B6: Presales - EXP Central Management | C6: Telecoms | D6: Telecoms | E6: Alina Nosulych | F6: Internal | G6: n/a | H6: 88100313 | I6: Ongoing | J6: 46023 | K6: 46387 | L6: EXP | M6: 0 | N6: 1 | O6: =M6*N6 -> 0 | P6: NGFW request check for EXP, allocation only
A7: Cookies and consent ​management transformation​ | B7: Cookies and DSAR management | C7: Telecoms | D7: Telecoms | E7: Andrea Stratilova | F7: Internal | G7: n/a | H7: 89101258 | I7: Ongoing | J7: 45901 | K7: 46387 | L7: Multiple | M7: 294645 | N7: 1 | O7: =M7*N7 -> 294645
A8: Demand Management (Whitelisting for ZPA and Cloud Proxy Service) | B8: Demand Management (Whitelisting for ZPA and Cloud Proxy Service) | C8: Telecoms | D8: Telecoms | E8: Andrea Stratilova | F8: Internal | G8: n/a | H8: 89100787, 89100999 | I8: Ongoing | J8: 46023 | K8: 46387 | L8: ITS | M8: 0 | N8: 1 | O8: =M8*N8 -> 0 | P8: allocation only, run
A9: NGFW Proposals (DSC, ….) | B9: NGFW Proposals (DSC, ….) | C9: Telecoms | D9: Telecoms | E9: Andrea Stratilova | F9: Internal | G9: n/a | H9: 88100294, 88100275, 89100826, 89101130 | I9: Ongoing | J9: 46023 | K9: 46387 | L9: Multiple | M9: 0 | N9: 1 | O9: =M9*N9 -> 0 | P9: NGFW request check for DSC and others Bus, allocation only
A10: ExpAM-17020-WIN 2016 OS Refresh MX | B10: EXP AM Win 2016 OS Refresh | C10: Americas | D10: Hosting Programs | E10: Carlos Crawford | F10: External | G10: Q-42762 | H10: 31318838 | I10: Ongoing | J10: 45931 | K10: 46022 | L10: EXP | M10: 37236.64 | N10: 1 | O10: =M10*N10 -> 37236.64
A11: DSCBR 22 Servers Migration to NAS | B11: DSCBR 22 Servers Migration to NAS | C11: Americas | D11: Telecoms | E11: Carlos Crawford | F11: External | G11: Q-44330 | H11: 31318789 | I11: Completed | J11: 45965 | K11: 46022 | L11: DSC | M11: 15486.16 | N11: 1 | O11: =M11*N11 -> 15486.16 | P11: closed in 2025, this year new order (FP) - line 119
A12: DSCUS New LPAR Optimus | B12: DSCUS New LPAR Optimus | C12: Americas | D12: Telecoms | E12: Carlos Crawford | F12: External | G12: Q-40690 | H12: 31318424 | I12: Completed | J12: 45831 | K12: 46081 | L12: DSC | M12: 1270.08 | N12: 1 | O12: =M12*N12 -> 1270.08 | P12: will be finished in 2026 (January)
A13: ExpAM-17029-DHCP Latam Migration | B13: ExpAM-17029-DHCP Latam Migration | C13: Americas | D13: Telecoms | E13: Carlos Crawford | F13: External | G13: Q-41773 | H13: 31319663 | I13: Ongoing | J13: 45993 | K13: 46265 | L13: EXP | M13: 34225.23 | N13: 1 | O13: =M13*N13 -> 34225.23
A14: DSCBR - DHCP Migration | B14: DSC - DHCP Migration | C14: Americas | D14: Telecoms | E14: Carlos Crawford | F14: External | G14: Q-44232 | H14: 31320039 | I14: Ongoing | J14: 46023 | K14: 46234 | L14: DSC | M14: 13344.31 | N14: 1 | O14: =M14*N14 -> 13344.31
A15: DSCMX - DHCP Migration | B15: DSC - DHCP Migration | C15: Americas | D15: Telecoms | E15: Carlos Crawford | F15: External | G15: Q-44233 | H15: 31320038 | I15: Ongoing | J15: 46023 | K15: 46173 | L15: DSC | M15: 7842.74 | N15: 1 | O15: =M15*N15 -> 7842.74
A16: DSCCO - DHCP Migration | B16: DSC - DHCP Migration | C16: Americas | D16: Telecoms | E16: Carlos Crawford | F16: External | G16: Q-44234 | H16: 31320037 | I16: Ongoing | J16: 46023 | K16: 46173 | L16: DSC | M16: 3911.85 | N16: 1 | O16: =M16*N16 -> 3911.85
A17: DSCBR 22 Servers Migration to NAS | B17: DSCBR 22 Servers Migration to NAS | C17: Americas | D17: Telecoms | E17: Carlos Crawford | F17: External | G17: Q-41949 | H17: 31319237 | I17: Ongoing | J17: 45883 | K17: 46203 | L17: DSC | M17: 15994 | N17: 1 | O17: =M17*N17 -> 15994 | P17: end in the middle of June
A18: Private Cloud 2.0 - Phase 1 | B18: Private Cloud 2.0 - Phase 1 | C18: APAC | D18: SEF | E18: Daniel Lai | F18: Internal | G18: 1091183860 | H18: 87101375 | I18: Completed | J18: 45901 | K18: 45716 | L18: ITS | M18: 533000 | N18: 1 | O18: 533000
A19: Private Cloud 2.0 - Phase 2 | B19: Private Cloud 2.0 - Phase 2 | C19: APAC | D19: SEF | E19: Daniel Lai | F19: Internal | G19: 1552930201 | H19: 87002033 | I19: Ongoing | J19: 46023 | K19: 46387 | L19: ITS | M19: 1420000 | N19: 1 | O19: =M19*N19 -> 1420000 | P19: value to be clarified (1.600 k)
A20: ExpAM-17020-WIN 2016 OS Refresh CR CSC | B20: EXP AM Win 2016 OS Refresh | C20: Americas | D20: Hosting Programs | E20: Daniela Ocampo | F20: External | G20: Q-42759 | H20: 31318835 | I20: Ongoing | J20: 45931 | K20: 46326 | L20: EXP | M20: 6817.92 | N20: 1 | O20: =M20*N20 -> 6817.92
A21: ExpAM-17020-WIN 2016 OS Refresh EC CSA | B21: EXP AM Win 2016 OS Refresh | C21: Americas | D21: Hosting Programs | E21: Daniela Ocampo | F21: External | G21: Q-42760 | H21: 31318836 | I21: Ongoing | J21: 45931 | K21: 46326 | L21: EXP | M21: 4849.6 | N21: 1 | O21: =M21*N21 -> 4849.6
A22: ExpAM-17020-WIN 2016 OS Refresh GT CSA | B22: EXP AM Win 2016 OS Refresh | C22: Americas | D22: Hosting Programs | E22: Daniela Ocampo | F22: External | G22: Q-42761 | H22: 31318837 | I22: Ongoing | J22: 45931 | K22: 46326 | L22: EXP | M22: 4849.6 | N22: 1 | O22: =M22*N22 -> 4849.6
A23: ExpAM-17020-WIN 2016 OS Refresh PY CSA | B23: EXP AM Win 2016 OS Refresh | C23: Americas | D23: Hosting Programs | E23: Daniela Ocampo | F23: External | G23: Q-42763 | H23: 31318839 | I23: Ongoing | J23: 45931 | K23: 46326 | L23: EXP | M23: 9699.2 | N23: 1 | O23: =M23*N23 -> 9699.2
A24: ExpAM-17020-WIN 2016 OS Refresh PE CSA | B24: EXP AM Win 2016 OS Refresh | C24: Americas | D24: Hosting Programs | E24: Daniela Ocampo | F24: External | G24: Q-42764 | H24: 31318840 | I24: Ongoing | J24: 45931 | K24: 46326 | L24: EXP | M24: 14548.8 | N24: 1 | O24: =M24*N24 -> 14548.8
A25: ExpAM-17020-WIN 2016 OS Refresh UY CSA | B25: EXP AM Win 2016 OS Refresh | C25: Americas | D25: Hosting Programs | E25: Daniela Ocampo | F25: External | G25: Q-42765 | H25: 31318841 | I25: Ongoing | J25: 45931 | K25: 46326 | L25: EXP | M25: 9699.2 | N25: 1 | O25: =M25*N25 -> 9699.2
A26: ExpAM-17020-WIN 2016 OS Refresh US | B26: EXP AM Win 2016 OS Refresh | C26: Americas | D26: Hosting Programs | E26: Daniela Ocampo | F26: External | G26: Q-42766 | H26: 31318842 | I26: Ongoing | J26: 45931 | K26: 46326 | L26: EXP | M26: 29097.6 | N26: 1 | O26: =M26*N26 -> 29097.6
A27: ExpAM-17020-WIN 2016 OS Refresh H&G | B27: EXP AM Win 2016 OS Refresh | C27: Americas | D27: Hosting Programs | E27: Daniela Ocampo | F27: External | G27: Q-42750 | H27: 31318843 | I27: Ongoing | J27: 45931 | K27: 46326 | L27: EXP | M27: 16517.12 | N27: 1 | O27: =M27*N27 -> 16517.12
A28: ExpAM-17020-WIN 2016 OS Refresh AR CSA | B28: EXP AM Win 2016 OS Refresh | C28: Americas | D28: Hosting Programs | E28: Daniela Ocampo | F28: External | G28: Q-42752 | H28: 31318844 | I28: Ongoing | J28: 45931 | K28: 46326 | L28: EXP | M28: 4849.6 | N28: 1 | O28: =M28*N28 -> 4849.6
A29: ExpAM-17020-WIN 2016 OS Refresh BR | B29: EXP AM Win 2016 OS Refresh | C29: Americas | D29: Hosting Programs | E29: Daniela Ocampo | F29: External | G29: Q-42754 | H29: 31318846 | I29: Ongoing | J29: 45931 | K29: 46326 | L29: EXP | M29: 9699.2 | N29: 1 | O29: =M29*N29 -> 9699.2
A30: ExpAM-17020-WIN 2016 OS Refresh CL CSA | B30: EXP AM Win 2016 OS Refresh | C30: Americas | D30: Hosting Programs | E30: Daniela Ocampo | F30: External | G30: Q-42756 | H30: 31318847 | I30: Ongoing | J30: 45931 | K30: 46326 | L30: EXP | M30: 9699.2 | N30: 1 | O30: =M30*N30 -> 9699.2
A31: ExpAM-17020-WIN 2016 OS Refresh CR CSA | B31: EXP AM Win 2016 OS Refresh | C31: Americas | D31: Hosting Programs | E31: Daniela Ocampo | F31: External | G31: Q-42758 | H31: 31318848 | I31: Ongoing | J31: 45931 | K31: 46326 | L31: EXP | M31: 9699.2 | N31: 1 | O31: =M31*N31 -> 9699.2
... A35: ExpAM-17020-WIN 2016 OS Refresh AM Regional | B35: EXP AM Win 2016 OS Refresh | C35: Americas | D35: Hosting Programs | E35: Daniela Ocampo | F35: External | G35: Q-42751 | H35: 31318852 | I35: Ongoing | J35: 45931 | K35: 46326 | L35: EXP | M35: 19398.4 | N35: 1 | O35: =M35*N35 -> 19398.4
A36: DSCUS IOT 3rd Party Management 5 Sites P | B36: DSCUS IOT 3rd Party Management 5 Sites P | C36: Americas | D36: Telecoms | E36: Daniela Ocampo | F36: External | G36: Q-41157 | H36: 31319201 | I36: Ongoing | J36: 45962 | K36: 46203 | L36: DSC | M36: 5239.44 | N36: 1 | O36: =M36*N36 -> 5239.44
A37: DeC US Impl. HA for CVG Honeywell Servers | B37: DeC US Impl. HA for CVG Honeywell Servers | C37: Americas | D37: Telecoms | E37: Daniela Ocampo | F37: External | G37: Q-19425 | H37: 31306768 | I37: Ongoing | J37: 45292 | K37: 46203 | L37: DeC | M37: 4413.2 | N37: 1 | O37: =M37*N37 -> 4413.2 | P37: will be changed to FP. 2024 - 8827 EUR, the project is going to 2026
A38: DeC US Impl. HA for ORD Honeywell Servers | B38: DeC US Impl. HA for ORD Honeywell Servers | C38: Americas | D38: Telecoms | E38: Daniela Ocampo | F38: External | G38: Q-19424 | H38: 31306767 | I38: Ongoing | J38: 45292 | K38: 46203 | L38: DeC | M38: 3258.92 | N38: 1 | O38: =M38*N38 -> 3258.92 | P38: the project is going to 2026
A39: ExpAM-16534-UCC Telephony 2024 BR | B39: ExpAM-16534-UCC Telephony 2024 BR | C39: Americas | D39: DWS | E39: Daniela Ocampo | F39: External | G39: Q-22966 | H39: 31315447 | I39: Completed | J39: 45870 | K39: 46081 | L39: EXP | M39: 0 | N39: 1 | O39: =M39*N39 -> 0
A40: EXP AM JFK SATS – SCADA | B40: EXP AM JFK SATS – SCADA | C40: Americas | D40: IS - Other | E40: Daniela Ocampo | F40: External | G40: Q-34347 | H40: 31316085 | I40: Completed | J40: 45748 | K40: 46053 | L40: EXP | M40: 0 | N40: 1 | O40: =M40*N40 -> 0
A41: ExpAM-17115-UCC Telephony Dominican Republic | B41: ExpAM UCC Telephony | C41: Americas | D41: DWS | E41: Daniela Ocampo | F41: External | G41: Q-44194 | H41: 31319983 | I41: Ongoing | J41: 46023 | K41: 46295 | L41: EXP | M41: 1858.4 | N41: 1 | O41: =M41*N41 -> 1858.4
A42: ExpAM-17115-UCC Telephony Bahamas | B42: ExpAM UCC Telephony | C42: Americas | D42: DWS | E42: Daniela Ocampo | F42: External | G42: Q-44195 | H42: 31319986 | I42: Ongoing | J42: 46023 | K42: 46295 | L42: EXP | M42: 1858.4 | N42: 1 | O42: =M42*N42 -> 1858.4
A43: ExpAM-17115-UCC Telephony Barbados | B43: ExpAM UCC Telephony | C43: Americas | D43: DWS | E43: Daniela Ocampo | F43: External | G43: Q-44196 | H43: 31319987 | I43: Ongoing | J43: 46023 | K43: 46295 | L43: EXP | M43: 1858.4 | N43: 1 | O43: =M43*N43 -> 1858.4
...

Sheet Project documentation
A1: Project name (as in ITS1) | B1: Tower | C1: PM name | D1: Externality | E1: BU | F1: Status | G1: Project Charter | H1: Project Charter reviewed by Hena | I1: Project Charter reviewed by Martin (SEF) | J1: Project Plan | K1: Resource plan | L1: PSR | M1: Lesson Learned | N1: Lessons Learned reviewed by Hena | O1: Project Closure | P1: Project Closure reviewed by Hena | Q1: Portfolio review scope | R1: Project Owner | S1: SEF | T1: RAG status | U1: 29th Jan scope | V1: 24th Feb scope | W1: 26th Mar scope | X1: 28th Apr scope | Y1: 28th May scope | Z1: 23rd June scope | AA1: Comment
A2: DSCUS New LPAR Optimus | B2: =VLOOKUP('Project documentation'!A2,'Project List 2026'!B:E,2,0) -> Americas | C2: =VLOOKUP(A2,'Project List 2026'!B:I,4,0) -> Carlos Crawford | D2: =VLOOKUP(A2,'Project List 2026'!B:F,5,0) -> External | E2: =VLOOKUP(A2,'Project List 2026'!B:L,11,0) -> DSC | F2: =VLOOKUP(A2,'Project List 2026'!B:I,8,0) -> Completed | G2: not required | H2: not required | J2: not required | K2: not required | L2: not required
A3: ExpAM-17029-DHCP Latam Migration | B3: =VLOOKUP('Project documentation'!A3,'Project List 2026'!B:E,2,0) -> Americas | C3: =VLOOKUP(A3,'Project List 2026'!B:I,4,0) -> Carlos Crawford | D3: =VLOOKUP(A3,'Project List 2026'!B:F,5,0) -> External | E3: =VLOOKUP(A3,'Project List 2026'!B:L,11,0) -> EXP | F3: =VLOOKUP(A3,'Project List 2026'!B:I,8,0) -> Ongoing | G3: yes | H3: 46132 | J3: yes | K3: yes | L3: PJ20252652
A4: DSC - DHCP Migration | B4: =VLOOKUP('Project documentation'!A4,'Project List 2026'!B:E,2,0) -> Americas | C4: =VLOOKUP(A4,'Project List 2026'!B:I,4,0) -> Carlos Crawford | D4: =VLOOKUP(A4,'Project List 2026'!B:F,5,0) -> External | E4: =VLOOKUP(A4,'Project List 2026'!B:L,11,0) -> DSC | F4: =VLOOKUP(A4,'Project List 2026'!B:I,8,0) -> Ongoing | G4: yes | H4: 46132 | J4: yes | K4: yes | L4: PJ20252837
A5: EXP AM Win 2016 OS Refresh | B5: =VLOOKUP('Project documentation'!A5,'Project List 2026'!B:E,2,0) -> Americas | C5: Daniela Ocampo/ Carlos Crawford (MX) | D5: =VLOOKUP(A5,'Project List 2026'!B:F,5,0) -> External | E5: =VLOOKUP(A5,'Project List 2026'!B:L,11,0) -> EXP | F5: =VLOOKUP(A5,'Project List 2026'!B:I,8,0) -> Ongoing | G5: yes | H5: 46132 | J5: yes | K5: yes | L5: PJ20252385 | Q5: Hosting | R5: Neeraja Duddu | X5: yes
A6: DSCBR 22 Servers Migration to NAS | B6: =VLOOKUP('Project documentation'!A6,'Project List 2026'!B:E,2,0) -> Americas | C6: =VLOOKUP(A6,'Project List 2026'!B:I,4,0) -> Carlos Crawford | D6: =VLOOKUP(A6,'Project List 2026'!B:F,5,0) -> External | E6: =VLOOKUP(A6,'Project List 2026'!B:L,11,0) -> DSC | F6: Ongoing | G6: yes | H6: 46132 | J6: yes | K6: yes | L6: PJ20252402
A7: DSCUS IOT 3rd Party Management 5 Sites P | B7: =VLOOKUP('Project documentation'!A7,'Project List 2026'!B:E,2,0) -> Americas | C7: =VLOOKUP(A7,'Project List 2026'!B:I,4,0) -> Daniela Ocampo | D7: =VLOOKUP(A7,'Project List 2026'!B:F,5,0) -> External | E7: =VLOOKUP(A7,'Project List 2026'!B:L,11,0) -> DSC | F7: =VLOOKUP(A7,'Project List 2026'!B:I,8,0) -> Ongoing | G7: yes | H7: 46132 | J7: yes | K7: yes | L7: PJ20252619
A8: ExpAM-16534-UCC Telephony 2024 BR | B8: =VLOOKUP('Project documentation'!A8,'Project List 2026'!B:E,2,0) -> Americas | C8: =VLOOKUP(A8,'Project List 2026'!B:I,4,0) -> Daniela Ocampo | D8: =VLOOKUP(A8,'Project List 2026'!B:F,5,0) -> External | E8: =VLOOKUP(A8,'Project List 2026'!B:L,11,0) -> EXP | F8: =VLOOKUP(A8,'Project List 2026'!B:I,8,0) -> Completed | G8: not required | J8: not required | K8: not required | L8: not required | M8: not required | O8: not required
A9: EXP AM JFK SATS – SCADA | B9: =VLOOKUP('Project documentation'!A9,'Project List 2026'!B:E,2,0) -> Americas | C9: =VLOOKUP(A9,'Project List 2026'!B:I,4,0) -> Daniela Ocampo | D9: =VLOOKUP(A9,'Project List 2026'!B:F,5,0) -> External | E9: =VLOOKUP(A9,'Project List 2026'!B:L,11,0) -> EXP | F9: =VLOOKUP(A9,'Project List 2026'!B:I,8,0) -> Completed | G9: not required | J9: not required | K9: not required | L9: not required | M9: not required | O9: not required
A10: ExpAM UCC Telephony | B10: =VLOOKUP('Project documentation'!A10,'Project List 2026'!B:E,2,0) -> Americas | C10: =VLOOKUP(A10,'Project List 2026'!B:I,4,0) -> Daniela Ocampo | D10: =VLOOKUP(A10,'Project List 2026'!B:F,5,0) -> External | E10: =VLOOKUP(A10,'Project List 2026'!B:L,11,0) -> EXP | F10: =VLOOKUP(A10,'Project List 2026'!B:I,8,0) -> Ongoing | G10: not required | J10: not required | K10: not required | L10: not required | M10: not required | O10: not required
A11: DSCUS Transport GovCloud Enclave BUILD P | B11: =VLOOKUP('Project documentation'!A11,'Project List 2026'!B:E,2,0) -> Americas | C11: =VLOOKUP(A11,'Project List 2026'!B:I,4,0) -> Dayanna Abarca | D11: =VLOOKUP(A11,'Project List 2026'!B:F,5,0) -> External | E11: =VLOOKUP(A11,'Project List 2026'!B:L,11,0) -> DSC | F11: =VLOOKUP(A11,'Project List 2026'!B:I,8,0) -> Ongoing | G11: yes | H11: 46052 | J11: yes | K11: yes | L11: PJ20251428 | M11: yes | R11: Zdenek Suchel
A12: DSCUS Inmar - Transition to DHL Standard | B12: =VLOOKUP('Project documentation'!A12,'Project List 2026'!B:E,2,0) -> Americas | C12: =VLOOKUP(A12,'Project List 2026'!B:I,4,0) -> William Exham | D12: =VLOOKUP(A12,'Project List 2026'!B:F,5,0) -> External | E12: =VLOOKUP(A12,'Project List 2026'!B:L,11,0) -> DSC | F12: =VLOOKUP(A12,'Project List 2026'!B:I,8,0) -> Ongoing | G12: yes | H12: 46052 | J12: yes | K12: yes | L12: PJ20251543 | Q12: Hosting | R12: Barbora Vesela | V12: yes | Z12: yes
A13: Private Cloud 2.0 - Phase 1 | B13: =VLOOKUP('Project documentation'!A13,'Project List 2026'!B:E,2,0) -> APAC | C13: =VLOOKUP(A13,'Project List 2026'!B:I,4,0) -> Daniel Lai | D13: =VLOOKUP(A13,'Project List 2026'!B:F,5,0) -> Internal | E13: =VLOOKUP(A13,'Project List 2026'!B:L,11,0) -> ITS | F13: =VLOOKUP(A13,'Project List 2026'!B:I,8,0) -> Completed | G13: yes | J13: yes | K13: yes | L13: yes | M13: In Progress | O13: In Progress | R13: Jan Havel | S13: yes | U13: yes
A14: Private Cloud 2.0 - Phase 2 | B14: =VLOOKUP('Project documentation'!A14,'Project List 2026'!B:E,2,0) -> APAC | C14: =VLOOKUP(A14,'Project List 2026'!B:I,4,0) -> Daniel Lai | D14: =VLOOKUP(A14,'Project List 2026'!B:F,5,0) -> Internal | E14: =VLOOKUP(A14,'Project List 2026'!B:L,11,0) -> ITS | F14: =VLOOKUP(A14,'Project List 2026'!B:I,8,0) -> Ongoing | G14: In Progress | H14: 46178 | I14: 46209 | J14: In Progress | K14: yes | L14: PJ20260357 | Q14: Hosting | R14: Amitabh | S14: yes | W14: yes
A15: EXP GL Resilience 2.0_ISQ_Automation | B15: =VLOOKUP('Project documentation'!A15,'Project List 2026'!B:E,2,0) -> APAC | C15: =VLOOKUP(A15,'Project List 2026'!B:I,4,0) -> Lisette Fincke | D15: =VLOOKUP(A15,'Project List 2026'!B:F,5,0) -> External | E15: =VLOOKUP(A15,'Project List 2026'!B:L,11,0) -> EXP | F15: =VLOOKUP(A15,'Project List 2026'!B:I,8,0) -> Ongoing | G15: yes | J15: yes | K15: yes | L15: PJ20241298 | Q15: Hosting | R15: Adrian Apthorp | W15: yes | Y15: yes
A16: FreeRadius Sunset | B16: =VLOOKUP('Project documentation'!A16,'Project List 2026'!B:E,2,0) -> APAC | C16: =VLOOKUP(A16,'Project List 2026'!B:I,4,0) -> Lisette Fincke | D16: =VLOOKUP(A16,'Project List 2026'!B:F,5,0) -> Internal | E16: =VLOOKUP(A16,'Project List 2026'!B:L,11,0) -> ITS | F16: =VLOOKUP(A16,'Project List 2026'!B:I,8,0) -> Ongoing | G16: not required | J16: not required | K16: not required | L16: not required | M16: not required | O16: not required | AA16: Lis is only receiving eTime for this project.
A17: ITS Infosec Program management | B17: =VLOOKUP('Project documentation'!A17,'Project List 2026'!B:E,2,0) -> APAC | C17: =VLOOKUP(A17,'Project List 2026'!B:I,4,0) -> Muhammad Yusry | D17: =VLOOKUP(A17,'Project List 2026'!B:F,5,0) -> Internal | E17: =VLOOKUP(A17,'Project List 2026'!B:L,11,0) -> ITS | F17: =VLOOKUP(A17,'Project List 2026'!B:I,8,0) -> Completed | G17: yes | J17: yes | K17: not required | L17: not required | M17: yes | O17: yes
A18: DSCAP-Windows_2016_EOS_Assessment | B18: =VLOOKUP('Project documentation'!A18,'Project List 2026'!B:E,2,0) -> APAC | C18: =VLOOKUP(A18,'Project List 2026'!B:I,4,0) -> Muhammad Yusry | D18: =VLOOKUP(A18,'Project List 2026'!B:F,5,0) -> External | E18: =VLOOKUP(A18,'Project List 2026'!B:L,11,0) -> DSC | F18: =VLOOKUP(A18,'Project List 2026'!B:I,8,0) -> Completed | G18: yes | K18: yes | L18: PJ20252307 | M18: yes | O18: In Progress | R18: Alvin Ho
A19: SPCS Managed Service – Transition from Cloud4C to ITS | B19: =VLOOKUP('Project documentation'!A19,'Project List 2026'!B:E,2,0) -> APAC | C19: =VLOOKUP(A19,'Project List 2026'!B:I,4,0) -> Muhammad Yusry | D19: =VLOOKUP(A19,'Project List 2026'!B:F,5,0) -> Internal | E19: =VLOOKUP(A19,'Project List 2026'!B:L,11,0) -> ITS | F19: =VLOOKUP(A19,'Project List 2026'!B:I,8,0) -> Ongoing | G19: In Progress | H19: 46185 | J19: In Progress | K19: yes | L19: PJ20260684 | M19: In Progress | R19: Jan Havel
A20: DC Fortigate Refresh 2nd Phase- GLOBAL | B20: =VLOOKUP('Project documentation'!A20,'Project List 2026'!B:E,2,0) -> APAC | C20: =VLOOKUP(A20,'Project List 2026'!B:I,4,0) -> Muhammad Yusry | D20: =VLOOKUP(A20,'Project List 2026'!B:F,5,0) -> Internal | E20: =VLOOKUP(A20,'Project List 2026'!B:L,11,0) -> ITS | F20: =VLOOKUP(A20,'Project List 2026'!B:I,8,0) -> Ongoing | G20: In Progress | H20: 46185 | J20: In Progress | K20: not required | L20: PJ20260240 | M20: In Progress | R20: Sannil Walson
A21: AP UCC Implementations | B21: =VLOOKUP('Project documentation'!A21,'Project List 2026'!B:E,2,0) -> APAC | C21: =VLOOKUP(A21,'Project List 2026'!B:I,4,0) -> Muthu Ramasamy | D21: =VLOOKUP(A21,'Project List 2026'!B:F,5,0) -> External | E21: =VLOOKUP(A21,'Project List 2026'!B:L,11,0) -> Multiple | F21: =VLOOKUP(A21,'Project List 2026'!B:I,8,0) -> Ongoing | G21: not required | J21: not required | K21: not required | L21: Multiple | M21: not required | O21: not required | AA21: DWS
A22: ExpMena-17127-DHCP Migration | B22: =VLOOKUP('Project documentation'!A22,'Project List 2026'!B:E,2,0) -> APAC | C22: =VLOOKUP(A22,'Project List 2026'!B:I,4,0) -> Muthu Ramasamy | D22: =VLOOKUP(A22,'Project List 2026'!B:F,5,0) -> External | E22: =VLOOKUP(A22,'Project List 2026'!B:L,11,0) -> EXP | F22: =VLOOKUP(A22,'Project List 2026'!B:I,8,0) -> Ongoing | G22: In Progress | H22: 46203 | J22: In Progress | K22: yes | L22: PJ20260217 | M22: In Progress
A23: ExpEU-17125- Spain DHCP Migration | B23: =VLOOKUP('Project documentation'!A23,'Project List 2026'!B:E,2,0) -> APAC | C23: =VLOOKUP(A23,'Project List 2026'!B:I,4,0) -> Muthu Ramasamy | D23: =VLOOKUP(A23,'Project List 2026'!B:F,5,0) -> External | E23: =VLOOKUP(A23,'Project List 2026'!B:L,11,0) -> EXP | F23: =VLOOKUP(A23,'Project List 2026'!B:I,8,0) -> Completed | G23: In Progress | H23: 46203 | J23: In Progress | K23: yes | L23: PJ20260128 | M23: In Progress
A24: Red Hat Ansible Deployment for ITS Servers | B24: =VLOOKUP('Project documentation'!A24,'Project List 2026'!B:E,2,0) -> APAC | C24: =VLOOKUP(A24,'Project List 2026'!B:I,4,0) -> Prosen Chandra | D24: =VLOOKUP(A24,'Project List 2026'!B:F,5,0) -> Internal | E24: =VLOOKUP(A24,'Project List 2026'!B:L,11,0) -> ITS | F24: =VLOOKUP(A24,'Project List 2026'!B:I,8,0) -> Ongoing | G24: yes | J24: yes | K24: yes | L24: PJ20240296 | M24: In Progress | Q24: Hosting | R24: Vit Rocek | S24: yes | U24: yes | W24: yes | Y24: yes
A25: Global consistent monitoring and Test servers monitoring | B25: =VLOOKUP('Project documentation'!A25,'Project List 2026'!B:E,2,0) -> APAC | C25: =VLOOKUP(A25,'Project List 2026'!B:I,4,0) -> Prosen Chandra | D25: =VLOOKUP(A25,'Project List 2026'!B:F,5,0) -> Internal | E25: =VLOOKUP(A25,'Project List 2026'!B:L,11,0) -> ITS | F25: =VLOOKUP(A25,'Project List 2026'!B:I,8,0) -> Completed | G25: yes | J25: yes | K25: not required | L25: yes | M25: yes | O25: yes
A26: Openshift integration into Netbackup | B26: =VLOOKUP('Project documentation'!A26,'Project List 2026'!B:E,2,0) -> #N/A | C26: =VLOOKUP(A26,'Project List 2026'!B:I,4,0) -> #N/A | D26: =VLOOKUP(A26,'Project List 2026'!B:F,5,0) -> #N/A | E26: =VLOOKUP(A26,'Project List 2026'!B:L,11,0) -> #N/A | F26: =VLOOKUP(A26,'Project List 2026'!B:I,8,0) -> #N/A | G26: yes | J26: yes | K26: not required | L26: PJ20240068 | M26: In Progress | Q26: Hosting | R26: Ondrej Svoboda | W26: yes
A27: Exchange Downgrade and Cloud Readiness | B27: =VLOOKUP('Project documentation'!A27,'Project List 2026'!B:E,2,0) -> #N/A | C27: =VLOOKUP(A27,'Project List 2026'!B:I,4,0) -> #N/A | D27: =VLOOKUP(A27,'Project List 2026'!B:F,5,0) -> #N/A | E27: =VLOOKUP(A27,'Project List 2026'!B:L,11,0) -> #N/A | F27: =VLOOKUP(A27,'Project List 2026'!B:I,8,0) -> #N/A | G27: not required | J27: not required | K27: not required | M27: not required | O27: not required | AA27: DWS
A28: M365 Tenant Configuration Backup & Recovery | B28: =VLOOKUP('Project documentation'!A28,'Project List 2026'!B:E,2,0) -> APAC | C28: =VLOOKUP(A28,'Project List 2026'!B:I,4,0) -> Ruthie Buenafe | D28: =VLOOKUP(A28,'Project List 2026'!B:F,5,0) -> Internal | E28: =VLOOKUP(A28,'Project List 2026'!B:L,11,0) -> ITS | F28: =VLOOKUP(A28,'Project List 2026'!B:I,8,0) -> Ongoing | G28: not required | J28: not required | K28: not required | M28: not required | O28: not required | AA28: DWS
A29: DGF-CN-HK-RIM-HOSTING Tech Refresh | B29: =VLOOKUP('Project documentation'!A29,'Project List 2026'!B:E,2,0) -> APAC | C29: =VLOOKUP(A29,'Project List 2026'!B:I,4,0) -> Saranyah Vairavan | D29: =VLOOKUP(A29,'Project List 2026'!B:F,5,0) -> External | E29: =VLOOKUP(A29,'Project List 2026'!B:L,11,0) -> DGFF | F29: =VLOOKUP(A29,'Project List 2026'!B:I,8,0) -> Ongoing | G29: yes | J29: In Progress | K29: yes | L29: PJ20251765 | M29: In Progress | Q29: Hosting | R29: Zdenek Novotny | Y29: yes
A30: DSC-GSL-B-SeLECT-Emulator migration-ITPM | B30: =VLOOKUP('Project documentation'!A30,'Project List 2026'!B:E,2,0) -> APAC | C30: =VLOOKUP(A30,'Project List 2026'!B:I,4,0) -> Saranyah Vairavan | D30: =VLOOKUP(A30,'Project List 2026'!B:F,5,0) -> External | E30: =VLOOKUP(A30,'Project List 2026'!B:L,11,0) -> DSC | F30: =VLOOKUP(A30,'Project List 2026'!B:I,8,0) -> Completed | G30: yes | J30: yes | K30: yes | L30: yes
A31: DSC-GSL-B-SeLECT-Emulator migration -ELR | B31: =VLOOKUP('Project documentation'!A31,'Project List 2026'!B:E,2,0) -> APAC | C31: =VLOOKUP(A31,'Project List 2026'!B:I,4,0) -> Saranyah Vairavan | D31: =VLOOKUP(A31,'Project List 2026'!B:F,5,0) -> External | E31: =VLOOKUP(A31,'Project List 2026'!B:L,11,0) -> DSC | F31: =VLOOKUP(A31,'Project List 2026'!B:I,8,0) -> Completed
A32: DGFF-AP-DGF-HK-RIM-HOSTING Tradelink 202 | B32: APAC | C32: =VLOOKUP(A32,'Project List 2026'!B:I,4,0) -> Saranyah Vairavan | D32: =VLOOKUP(A32,'Project List 2026'!B:F,5,0) -> External | E32: =VLOOKUP(A32,'Project List 2026'!B:L,11,0) -> DGFF | F32: =VLOOKUP(A32,'Project List 2026'!B:I,8,0) -> Ongoing | G32: yes | J32: In Progress | L32: PJ20252762 | M32: In Progress | Q32: Hosting
A33: DSC FR - Infolog upgrade IT PM | B33: =VLOOKUP('Project documentation'!A33,'Project List 2026'!B:E,2,0) -> Hosting | C33: =VLOOKUP(A33,'Project List 2026'!B:I,4,0) -> Hana Kodatova | D33: =VLOOKUP(A33,'Project List 2026'!B:F,5,0) -> External | E33: =VLOOKUP(A33,'Project List 2026'!B:L,11,0) -> DSC | F33: =VLOOKUP(A33,'Project List 2026'!B:I,8,0) -> Completed | G33: yes | H33: 2025 | J33: yes | K33: yes | L33: PJ20251811 | M33: yes | N33: 2025 | O33: yes | P33: 2025 | R33: Sylvain Lepine | V33: yes
A34: EXP AP Ws2016 OS Refresh - Discovery & Design | B34: APAC | C34: =VLOOKUP(A34,'Project List 2026'!B:I,4,0) -> Saranyah Vairavan | D34: =VLOOKUP(A34,'Project List 2026'!B:F,5,0) -> External | E34: =VLOOKUP(A34,'Project List 2026'!B:L,11,0) -> EXP | F34: Initiation | K34: yes | Q34: Hosting
A35: Secure API Testing - Service Introduction | B35: =VLOOKUP('Project documentation'!A35,'Project List 2026'!B:E,2,0) -> Hosting | C35: =VLOOKUP(A35,'Project List 2026'!B:I,4,0) -> Hana Sinska | D35: =VLOOKUP(A35,'Project List 2026'!B:F,5,0) -> Internal | E35: =VLOOKUP(A35,'Project List 2026'!B:L,11,0) -> ITS | F35: =VLOOKUP(A35,'Project List 2026'!B:I,8,0) -> Ongoing | G35: yes | H35: 46090 | J35: yes | K35: yes | L35: PJ20251996 | M35: yes | Q35: ?
A36: Green Accounting - MVP - Reporting 2024 | B36: =VLOOKUP('Project documentation'!A36,'Project List 2026'!B:E,2,0) -> Hosting | C36: =VLOOKUP(A36,'Project List 2026'!B:I,4,0) -> Hana Sinska | D36: =VLOOKUP(A36,'Project List 2026'!B:F,5,0) -> Internal | E36: =VLOOKUP(A36,'Project List 2026'!B:L,11,0) -> ITS | F36: =VLOOKUP(A36,'Project List 2026'!B:I,8,0) -> On hold | G36: yes | K36: yes | L36: PJ20240627
A37: Discovery Inventory PoC | B37: =VLOOKUP('Project documentation'!A37,'Project List 2026'!B:E,2,0) -> Hosting | C37: =VLOOKUP(A37,'Project List 2026'!B:I,4,0) -> Hana Kodatova | D37: =VLOOKUP(A37,'Project List 2026'!B:F,5,0) -> Internal | E37: =VLOOKUP(A37,'Project List 2026'!B:L,11,0) -> ITS | F37: =VLOOKUP(A37,'Project List 2026'!B:I,8,0) -> Ongoing | G37: yes | H37: 46125 | K37: yes | L37: PJ20260506 | Q37: Hosting | R37: Ales Trekoval | X37: yes | Z37: yes
A38: Storage TR 2026 | B38: =VLOOKUP('Project documentation'!A38,'Project List 2026'!B:E,2,0) -> Hosting | C38: =VLOOKUP(A38,'Project List 2026'!B:I,4,0) -> Hana Kodatova | D38: =VLOOKUP(A38,'Project List 2026'!B:F,5,0) -> Internal | E38: =VLOOKUP(A38,'Project List 2026'!B:L,11,0) -> ITS | F38: =VLOOKUP(A38,'Project List 2026'!B:I,8,0) -> Ongoing | G38: yes | L38: PJ20260327 | Q38: Hosting | R38: Pavel Lipavsky | Y38: yes
A39: Dell Server Onboarding | B39: =VLOOKUP('Project documentation'!A37,'Project List 2026'!B:E,2,0) -> Hosting | C39: =VLOOKUP(A39,'Project List 2026'!B:I,4,0) -> Hana Sinska | D39: =VLOOKUP(A39,'Project List 2026'!B:F,5,0) -> Internal | E39: =VLOOKUP(A39,'Project List 2026'!B:L,11,0) -> ITS | F39: =VLOOKUP(A39,'Project List 2026'!B:I,8,0) -> Ongoing | K39: yes | L39: PJ20261057 | Q39: Hosting | R39: Jan Havel | X39: yes
A40: PoC - BMC - OpenShift onboarding | B40: =VLOOKUP('Project documentation'!A40,'Project List 2026'!B:E,2,0) -> Hosting | C40: =VLOOKUP(A40,'Project List 2026'!B:I,4,0) -> Ivan Godunov | D40: =VLOOKUP(A40,'Project List 2026'!B:F,5,0) -> Internal | E40: =VLOOKUP(A40,'Project List 2026'!B:L,11,0) -> ITS | F40: =VLOOKUP(A40,'Project List 2026'!B:I,8,0) -> Completed | G40: yes | H40: 46090 | J40: yes | K40: not required | L40: not required
...

Sheet Individual Allocation
A1: DO NOT EDIT | B1: DO NOT EDIT | C1: DO NOT EDIT | D1: DO NOT EDIT | E1: EDIT | F1: EDIT | G1: DO NOT EDIT | H1: DO NOT EDIT | I1: EDIT | J1: DO NOT EDIT | K1: DO NOT EDIT | L1: DO NOT EDIT | M1: Allocation % 2026 - PLEASE EDIT MANUALLY | S1: Allocation % 2026 - PLEASE EDIT MANUALLY | Y1: DO NOT EDIT
A2: Initial IP Tower | B2: Profit Ownership | C2: PM Depart | D2: PM Name | E2: PM Name Secondary | F2: Project name | G2: Externality | H2: Order N. | I2: Notes | J2: Value | K2: Project status | L2: Probability | M2: Jan | N2: Feb | O2: Mar | P2: Apr | Q2: May | R2: Jun | S2: Jul | T2: Aug | U2: Sep | V2: Oct | W2: Nov | X2: Dec | Y2: Is it in project list?
A3: =IF(F3=""," ",VLOOKUP(F3,'Project List 2026'!A:J,3,0)) -> Telecoms | B3: =IF(F3=""," ",VLOOKUP(F3,'Project List 2026'!A:N,4,0)) -> Others | C3: =IF(F3=""," ",VLOOKUP(E3,RefData!AG:AH,2,FALSE)) -> Telecoms | D3: =IF(F3=""," ",VLOOKUP(F3,'Project List 2026'!A:J,5,0)) -> Alina Nosulych | E3: Alina Nosulych | F3: BARN Security Enforcement | G3: =IF(F3=""," ",VLOOKUP(F3,'Project List 2026'!A:J,6,0)) -> Internal | H3: =IF(F3="","",VLOOKUP(F3,'Project List 2026'!A:H,8,0)) -> 89100298 | J3: =IF(F3=""," ",VLOOKUP(F3,'Project List 2026'!A:O,15,0)) -> 0 | K3: =IF(F3=""," ",VLOOKUP(F3,'Project List 2026'!A:T,9,0)) -> Ongoing | L3: =IF(F3=""," ",VLOOKUP(F3,'Project List 2026'!A:N,14,0)) -> 1 | P3: 0.2 | Q3: 0.2 | R3: 0.2 | Y3: =IF(ISNA(VLOOKUP(F3,'Project List 2026'!A:A,1,FALSE)), "No", "Yes") -> Yes
A4: =IF(F4=""," ",VLOOKUP(F4,'Project List 2026'!A:J,3,0)) -> Telecoms | B4: =IF(F4=""," ",VLOOKUP(F4,'Project List 2026'!A:N,4,0)) -> Telecoms | C4: =IF(F4=""," ",VLOOKUP(E4,RefData!AG:AH,2,FALSE)) -> Telecoms | D4: =IF(F4=""," ",VLOOKUP(F4,'Project List 2026'!A:J,5,0)) -> Alina Nosulych | E4: Alina Nosulych | F4: F5 Refresh | G4: =IF(F4=""," ",VLOOKUP(F4,'Project List 2026'!A:J,6,0)) -> Internal | H4: =IF(F4="","",VLOOKUP(F4,'Project List 2026'!A:H,8,0)) -> 87101386 | J4: =IF(F4=""," ",VLOOKUP(F4,'Project List 2026'!A:O,15,0)) -> 0 | K4: =IF(F4=""," ",VLOOKUP(F4,'Project List 2026'!A:T,9,0)) -> Ongoing | L4: =IF(F4=""," ",VLOOKUP(F4,'Project List 2026'!A:N,14,0)) -> 1 | M4: 0.4 | N4: 0.4 | O4: 0.4 | P4: 0.4 | Q4: 0.4 | R4: 0.4 | S4: 0.4 | T4: 0.4 | U4: 0.4 | V4: 0.4 | W4: 0.4 | Y4: =IF(ISNA(VLOOKUP(F4,'Project List 2026'!A:A,1,FALSE)), "No", "Yes") -> Yes
A5: =IF(F5=""," ",VLOOKUP(F5,'Project List 2026'!A:J,3,0)) -> Telecoms | B5: =IF(F5=""," ",VLOOKUP(F5,'Project List 2026'!A:N,4,0)) -> Telecoms | C5: =IF(F5=""," ",VLOOKUP(E5,RefData!AG:AH,2,FALSE)) -> Telecoms | D5: =IF(F5=""," ",VLOOKUP(F5,'Project List 2026'!A:J,5,0)) -> Alina Nosulych | E5: Alina Nosulych | F5: ACI Upgrade - global activitiy (BARN related) | G5: =IF(F5=""," ",VLOOKUP(F5,'Project List 2026'!A:J,6,0)) -> Internal | H5: =IF(F5="","",VLOOKUP(F5,'Project List 2026'!A:H,8,0)) -> 89100298 | J5: =IF(F5=""," ",VLOOKUP(F5,'Project List 2026'!A:O,15,0)) -> 0 | K5: =IF(F5=""," ",VLOOKUP(F5,'Project List 2026'!A:T,9,0)) -> Completed | L5: =IF(F5=""," ",VLOOKUP(F5,'Project List 2026'!A:N,14,0)) -> 1 | N5: 0.2 | O5: 0.2 | P5: 0.2 | Y5: =IF(ISNA(VLOOKUP(F5,'Project List 2026'!A:A,1,FALSE)), "No", "Yes") -> Yes
A6: =IF(F6=""," ",VLOOKUP(F6,'Project List 2026'!A:J,3,0)) -> Telecoms | B6: =IF(F6=""," ",VLOOKUP(F6,'Project List 2026'!A:N,4,0)) -> Telecoms | C6: =IF(F6=""," ",VLOOKUP(E6,RefData!AG:AH,2,FALSE)) -> Telecoms | D6: =IF(F6=""," ",VLOOKUP(F6,'Project List 2026'!A:J,5,0)) -> Alina Nosulych | E6: Alina Nosulych | F6: Central FAX migration to eFAX solution | G6: =IF(F6=""," ",VLOOKUP(F6,'Project List 2026'!A:J,6,0)) -> Internal | H6: =IF(F6="","",VLOOKUP(F6,'Project List 2026'!A:H,8,0)) -> 89100536 | J6: =IF(F6=""," ",VLOOKUP(F6,'Project List 2026'!A:O,15,0)) -> 0 | K6: =IF(F6=""," ",VLOOKUP(F6,'Project List 2026'!A:T,9,0)) -> Completed | L6: =IF(F6=""," ",VLOOKUP(F6,'Project List 2026'!A:N,14,0)) -> 1 | M6: 0.2 | N6: 0.2 | O6: 0.2 | P6: 0.2 | Y6: =IF(ISNA(VLOOKUP(F6,'Project List 2026'!A:A,1,FALSE)), "No", "Yes") -> Yes
A7: =IF(F7=""," ",VLOOKUP(F7,'Project List 2026'!A:J,3,0)) -> Telecoms | B7: =IF(F7=""," ",VLOOKUP(F7,'Project List 2026'!A:N,4,0)) -> Telecoms | C7: =IF(F7=""," ",VLOOKUP(E7,RefData!AG:AH,2,FALSE)) -> Telecoms | D7: =IF(F7=""," ",VLOOKUP(F7,'Project List 2026'!A:J,5,0)) -> Alina Nosulych | E7: Alina Nosulych | F7: NGFW Proposals EXP | G7: =IF(F7=""," ",VLOOKUP(F7,'Project List 2026'!A:J,6,0)) -> Internal | H7: =IF(F7="","",VLOOKUP(F7,'Project List 2026'!A:H,8,0)) -> 88100313 | J7: =IF(F7=""," ",VLOOKUP(F7,'Project List 2026'!A:O,15,0)) -> 0 | K7: =IF(F7=""," ",VLOOKUP(F7,'Project List 2026'!A:T,9,0)) -> Ongoing | L7: =IF(F7=""," ",VLOOKUP(F7,'Project List 2026'!A:N,14,0)) -> 1 | M7: 0.05 | N7: 0.05 | O7: 0.05 | P7: 0.05 | Q7: 0.05 | R7: 0.05 | S7: 0.05 | T7: 0.05 | U7: 0.05 | V7: 0.05 | W7: 0.05 | Y7: =IF(ISNA(VLOOKUP(F7,'Project List 2026'!A:A,1,FALSE)), "No", "Yes") -> Yes
A8: =IF(F8=""," ",VLOOKUP(F8,'Project List 2026'!A:J,3,0)) -> Telecoms | B8: =IF(F8=""," ",VLOOKUP(F8,'Project List 2026'!A:N,4,0)) -> Telecoms | C8: =IF(F8=""," ",VLOOKUP(E8,RefData!AG:AH,2,FALSE)) -> Telecoms | D8: =IF(F8=""," ",VLOOKUP(F8,'Project List 2026'!A:J,5,0)) -> Andrea Stratilova | E8: Andrea Stratilova | F8: Cookies and consent ​management transformation​ | G8: =IF(F8=""," ",VLOOKUP(F8,'Project List 2026'!A:J,6,0)) -> Internal | H8: =IF(F8="","",VLOOKUP(F8,'Project List 2026'!A:H,8,0)) -> 89101258 | J8: =IF(F8=""," ",VLOOKUP(F8,'Project List 2026'!A:O,15,0)) -> 294645 | K8: =IF(F8=""," ",VLOOKUP(F8,'Project List 2026'!A:T,9,0)) -> Ongoing | L8: =IF(F8=""," ",VLOOKUP(F8,'Project List 2026'!A:N,14,0)) -> 1 | M8: 0.3 | N8: 0.3 | O8: 0.3 | P8: 0.3 | Q8: 0.3 | R8: 0.3 | S8: 0.3 | T8: 0.3 | U8: 0.3 | V8: 0.3 | W8: 0.3 | X8: 0.3 | Y8: =IF(ISNA(VLOOKUP(F8,'Project List 2026'!A:A,1,FALSE)), "No", "Yes") -> Yes
A9: =IF(F9=""," ",VLOOKUP(F9,'Project List 2026'!A:J,3,0)) -> Telecoms | B9: =IF(F9=""," ",VLOOKUP(F9,'Project List 2026'!A:N,4,0)) -> Telecoms | C9: =IF(F9=""," ",VLOOKUP(E9,RefData!AG:AH,2,FALSE)) -> Telecoms | D9: =IF(F9=""," ",VLOOKUP(F9,'Project List 2026'!A:J,5,0)) -> Andrea Stratilova | E9: Andrea Stratilova | F9: Demand Management (Whitelisting for ZPA and Cloud Proxy Service) | G9: =IF(F9=""," ",VLOOKUP(F9,'Project List 2026'!A:J,6,0)) -> Internal | H9: =IF(F9="","",VLOOKUP(F9,'Project List 2026'!A:H,8,0)) -> 89100787, 89100999 | J9: =IF(F9=""," ",VLOOKUP(F9,'Project List 2026'!A:O,15,0)) -> 0 | K9: =IF(F9=""," ",VLOOKUP(F9,'Project List 2026'!A:T,9,0)) -> Ongoing | L9: =IF(F9=""," ",VLOOKUP(F9,'Project List 2026'!A:N,14,0)) -> 1 | M9: 0.05 | N9: 0.05 | O9: 0.05 | P9: 0.05 | Q9: 0.05 | R9: 0.05 | S9: 0.05 | T9: 0.05 | U9: 0.05 | V9: 0.05 | W9: 0.05 | X9: 0.05 | Y9: =IF(ISNA(VLOOKUP(F9,'Project List 2026'!A:A,1,FALSE)), "No", "Yes") -> Yes
A10: =IF(F10=""," ",VLOOKUP(F10,'Project List 2026'!A:J,3,0)) -> APAC | B10: =IF(F10=""," ",VLOOKUP(F10,'Project List 2026'!A:N,4,0)) -> SEF | C10: =IF(F10=""," ",VLOOKUP(E10,RefData!AG:AH,2,FALSE)) -> Telecoms | D10: =IF(F10=""," ",VLOOKUP(F10,'Project List 2026'!A:J,5,0)) -> Daniel Lai | E10: Andrea Stratilova | F10: Private Cloud 2.0 - Phase 2 | G10: =IF(F10=""," ",VLOOKUP(F10,'Project List 2026'!A:J,6,0)) -> Internal | H10: =IF(F10="","",VLOOKUP(F10,'Project List 2026'!A:H,8,0)) -> 87002033 | J10: =IF(F10=""," ",VLOOKUP(F10,'Project List 2026'!A:O,15,0)) -> 1420000 | K10: =IF(F10=""," ",VLOOKUP(F10,'Project List 2026'!A:T,9,0)) -> Ongoing | L10: =IF(F10=""," ",VLOOKUP(F10,'Project List 2026'!A:N,14,0)) -> 1 | M10: 0.1 | N10: 0.1 | O10: 0.1 | P10: 0.1 | Q10: 0.1 | R10: 0.1 | S10: 0.1 | T10: 0.1 | Y10: =IF(ISNA(VLOOKUP(F10,'Project List 2026'!A:A,1,FALSE)), "No", "Yes") -> Yes
A11: =IF(F11=""," ",VLOOKUP(F11,'Project List 2026'!A:J,3,0)) -> Telecoms | B11: =IF(F11=""," ",VLOOKUP(F11,'Project List 2026'!A:N,4,0)) -> Telecoms | C11: =IF(F11=""," ",VLOOKUP(E11,RefData!AG:AH,2,FALSE)) -> Telecoms | D11: =IF(F11=""," ",VLOOKUP(F11,'Project List 2026'!A:J,5,0)) -> Andrea Stratilova | E11: Andrea Stratilova | F11: NGFW Proposals (DSC, ….) | G11: =IF(F11=""," ",VLOOKUP(F11,'Project List 2026'!A:J,6,0)) -> Internal | H11: =IF(F11="","",VLOOKUP(F11,'Project List 2026'!A:H,8,0)) -> 88100294, 88100275, 89100826, 89101130 | J11: =IF(F11=""," ",VLOOKUP(F11,'Project List 2026'!A:O,15,0)) -> 0 | K11: =IF(F11=""," ",VLOOKUP(F11,'Project List 2026'!A:T,9,0)) -> Ongoing | L11: =IF(F11=""," ",VLOOKUP(F11,'Project List 2026'!A:N,14,0)) -> 1 | M11: 0.02 | N11: 0.02 | O11: 0.02 | P11: 0.02 | Q11: 0.02 | R11: 0.02 | S11: 0.02 | T11: 0.02 | U11: 0.02 | V11: 0.02 | W11: 0.02 | Y11: =IF(ISNA(VLOOKUP(F11,'Project List 2026'!A:A,1,FALSE)), "No", "Yes") -> Yes
A12: =IF(F12=""," ",VLOOKUP(F12,'Project List 2026'!A:J,3,0)) -> APAC | B12: =IF(F12=""," ",VLOOKUP(F12,'Project List 2026'!A:N,4,0)) -> SEF | C12: =IF(F12=""," ",VLOOKUP(E12,RefData!AG:AH,2,FALSE)) -> Telecoms-APAC | D12: =IF(F12=""," ",VLOOKUP(F12,'Project List 2026'!A:J,5,0)) -> Daniel Lai | E12: Daniel Lai | F12: Private Cloud 2.0 - Phase 1 | G12: =IF(F12=""," ",VLOOKUP(F12,'Project List 2026'!A:J,6,0)) -> Internal | H12: =IF(F12="","",VLOOKUP(F12,'Project List 2026'!A:H,8,0)) -> 87101375 | J12: =IF(F12=""," ",VLOOKUP(F12,'Project List 2026'!A:O,15,0)) -> 533000 | K12: =IF(F12=""," ",VLOOKUP(F12,'Project List 2026'!A:T,9,0)) -> Completed | L12: =IF(F12=""," ",VLOOKUP(F12,'Project List 2026'!A:N,14,0)) -> 1 | M12: 0.25 | N12: 0.25 | O12: 0.25 | Y12: =IF(ISNA(VLOOKUP(F12,'Project List 2026'!A:A,1,FALSE)), "No", "Yes") -> Yes
A13: =IF(F13=""," ",VLOOKUP(F13,'Project List 2026'!A:J,3,0)) -> APAC | B13: =IF(F13=""," ",VLOOKUP(F13,'Project List 2026'!A:N,4,0)) -> SEF | C13: =IF(F13=""," ",VLOOKUP(E13,RefData!AG:AH,2,FALSE)) -> Telecoms-APAC | D13: =IF(F13=""," ",VLOOKUP(F13,'Project List 2026'!A:J,5,0)) -> Daniel Lai | E13: Daniel Lai | F13: Private Cloud 2.0 - Phase 2 | G13: =IF(F13=""," ",VLOOKUP(F13,'Project List 2026'!A:J,6,0)) -> Internal | H13: =IF(F13="","",VLOOKUP(F13,'Project List 2026'!A:H,8,0)) -> 87002033 | J13: =IF(F13=""," ",VLOOKUP(F13,'Project List 2026'!A:O,15,0)) -> 1420000 | K13: =IF(F13=""," ",VLOOKUP(F13,'Project List 2026'!A:T,9,0)) -> Ongoing | L13: =IF(F13=""," ",VLOOKUP(F13,'Project List 2026'!A:N,14,0)) -> 1 | M13: 0.5 | N13: 0.5 | O13: 0.5 | P13: 0.5 | Q13: 0.5 | R13: 0.5 | S13: 0.5 | T13: 0.5 | U13: 0.5 | V13: 0.5 | W13: 0.5 | X13: 0.5 | Y13: =IF(ISNA(VLOOKUP(F13,'Project List 2026'!A:A,1,FALSE)), "No", "Yes") -> Yes
A14: =IF(F14=""," ",VLOOKUP(F14,'Project List 2026'!A:J,3,0)) -> Telecoms | B14: =IF(F14=""," ",VLOOKUP(F14,'Project List 2026'!A:N,4,0)) -> SEF | C14: =IF(F14=""," ",VLOOKUP(E14,RefData!AG:AH,2,FALSE)) -> Telecoms | D14: =IF(F14=""," ",VLOOKUP(F14,'Project List 2026'!A:J,5,0)) -> Dilyara Zeletdinova | E14: Dilyara Zeletdinova | F14: DNS and Domain management transformation | G14: =IF(F14=""," ",VLOOKUP(F14,'Project List 2026'!A:J,6,0)) -> Internal | H14: =IF(F14="","",VLOOKUP(F14,'Project List 2026'!A:H,8,0)) -> 87101423 | J14: =IF(F14=""," ",VLOOKUP(F14,'Project List 2026'!A:O,15,0)) -> 1002000 | K14: =IF(F14=""," ",VLOOKUP(F14,'Project List 2026'!A:T,9,0)) -> Ongoing | L14: =IF(F14=""," ",VLOOKUP(F14,'Project List 2026'!A:N,14,0)) -> 1 | M14: 0.2 | N14: 0.5 | O14: 0.5 | P14: 0.5 | Q14: 0.5 | R14: 0.5 | S14: 0.5 | T14: 0.5 | U14: 0.5 | V14: 0.5 | W14: 0.5 | X14: 0.5 | Y14: =IF(ISNA(VLOOKUP(F14,'Project List 2026'!A:A,1,FALSE)), "No", "Yes") -> Yes
A15: =IF(F15=""," ",VLOOKUP(F15,'Project List 2026'!A:J,3,0)) -> Telecoms | B15: =IF(F15=""," ",VLOOKUP(F15,'Project List 2026'!A:N,4,0)) -> Telecoms | C15: =IF(F15=""," ",VLOOKUP(E15,RefData!AG:AH,2,FALSE)) -> Telecoms | D15: =IF(F15=""," ",VLOOKUP(F15,'Project List 2026'!A:J,5,0)) -> Dilyara Zeletdinova | E15: Dilyara Zeletdinova | F15: Secure Access Portal Process and Architecture Modernization (ELM) | G15: =IF(F15=""," ",VLOOKUP(F15,'Project List 2026'!A:J,6,0)) -> Internal | H15: =IF(F15="","",VLOOKUP(F15,'Project List 2026'!A:H,8,0)) -> 0 | J15: =IF(F15=""," ",VLOOKUP(F15,'Project List 2026'!A:O,15,0)) -> 0 | K15: =IF(F15=""," ",VLOOKUP(F15,'Project List 2026'!A:T,9,0)) -> On hold | L15: =IF(F15=""," ",VLOOKUP(F15,'Project List 2026'!A:N,14,0)) -> 0.75 | M15: 0.25 | N15: 0.25 | O15: 0.25 | P15: 0.25 | Q15: 0.25 | R15: 0.25 | S15: 0.25 | T15: 0.25 | U15: 0.25 | V15: 0.25 | W15: 0.25 | X15: 0.25 | Y15: =IF(ISNA(VLOOKUP(F15,'Project List 2026'!A:A,1,FALSE)), "No", "Yes") -> Yes
A16: =IF(F16=""," ",VLOOKUP(F16,'Project List 2026'!A:J,3,0)) -> Telecoms | B16: =IF(F16=""," ",VLOOKUP(F16,'Project List 2026'!A:N,4,0)) -> Telecoms | C16: =IF(F16=""," ",VLOOKUP(E16,RefData!AG:AH,2,FALSE)) -> Telecoms | D16: =IF(F16=""," ",VLOOKUP(F16,'Project List 2026'!A:J,5,0)) -> Dilyara Zeletdinova | E16: Dilyara Zeletdinova | F16: Strengthen Deficiency (Consequence) Management for ELM - Phase II. | G16: =IF(F16=""," ",VLOOKUP(F16,'Project List 2026'!A:J,6,0)) -> Internal | H16: =IF(F16="","",VLOOKUP(F16,'Project List 2026'!A:H,8,0)) -> 0 | J16: =IF(F16=""," ",VLOOKUP(F16,'Project List 2026'!A:O,15,0)) -> 0 | K16: =IF(F16=""," ",VLOOKUP(F16,'Project List 2026'!A:T,9,0)) -> Ongoing | L16: =IF(F16=""," ",VLOOKUP(F16,'Project List 2026'!A:N,14,0)) -> 0.75 | M16: 0.25 | N16: 0.25 | O16: 0.25 | P16: 0.25 | Q16: 0.25 | R16: 0.25 | S16: 0.25 | T16: 0.25 | U16: 0.25 | V16: 0.25 | W16: 0.25 | X16: 0.25 | Y16: =IF(ISNA(VLOOKUP(F16,'Project List 2026'!A:A,1,FALSE)), "No", "Yes") -> Yes
A17: =IF(F17=""," ",VLOOKUP(F17,'Project List 2026'!A:J,3,0)) -> Telecoms | B17: =IF(F17=""," ",VLOOKUP(F17,'Project List 2026'!A:N,4,0)) -> Others | C17: =IF(F17=""," ",VLOOKUP(E17,RefData!AG:AH,2,FALSE)) -> Telecoms | D17: =IF(F17=""," ",VLOOKUP(F17,'Project List 2026'!A:J,5,0)) -> Jaroslav Kral | E17: Dilyara Zeletdinova | F17: ADaM 2.0 GCISO | G17: =IF(F17=""," ",VLOOKUP(F17,'Project List 2026'!A:J,6,0)) -> Internal | H17: =IF(F17="","",VLOOKUP(F17,'Project List 2026'!A:H,8,0)) -> 87101359 | J17: =IF(F17=""," ",VLOOKUP(F17,'Project List 2026'!A:O,15,0)) -> 0 | K17: =IF(F17=""," ",VLOOKUP(F17,'Project List 2026'!A:T,9,0)) -> Ongoing | L17: =IF(F17=""," ",VLOOKUP(F17,'Project List 2026'!A:N,14,0)) -> 1 | M17: 0.2 | N17: 0.2 | O17: 0.2 | Y17: =IF(ISNA(VLOOKUP(F17,'Project List 2026'!A:A,1,FALSE)), "No", "Yes") -> Yes
A18: =IF(F18=""," ",VLOOKUP(F18,'Project List 2026'!A:J,3,0)) -> Hosting | B18: =IF(F18=""," ",VLOOKUP(F18,'Project List 2026'!A:N,4,0)) -> Hosting Programs | C18: =IF(F18=""," ",VLOOKUP(E18,RefData!AG:AH,2,FALSE)) -> Infra Services | D18: =IF(F18=""," ",VLOOKUP(F18,'Project List 2026'!A:J,5,0)) -> Katerina Soukupova | E18: Hana Kodatova | F18: SATs central PM order | G18: =IF(F18=""," ",VLOOKUP(F18,'Project List 2026'!A:J,6,0)) -> External | H18: =IF(F18="","",VLOOKUP(F18,'Project List 2026'!A:H,8,0)) -> 31319957 | J18: =IF(F18=""," ",VLOOKUP(F18,'Project List 2026'!A:O,15,0)) -> 474281 | K18: =IF(F18=""," ",VLOOKUP(F18,'Project List 2026'!A:T,9,0)) -> Ongoing | L18: =IF(F18=""," ",VLOOKUP(F18,'Project List 2026'!A:N,14,0)) -> 1 | M18: 0.5 | N18: 0.5 | O18: 0.4 | R18: 0.4 | T18: 0.5 | U18: 0.5 | V18: 0.5 | W18: 0.5 | X18: 0.5 | Y18: =IF(ISNA(VLOOKUP(F18,'Project List 2026'!A:A,1,FALSE)), "No", "Yes") -> Yes
A19: =IF(F19=""," ",VLOOKUP(F19,'Project List 2026'!A:J,3,0)) -> Hosting | B19: =IF(F19=""," ",VLOOKUP(F19,'Project List 2026'!A:N,4,0)) -> IS - Other | C19: Infra Services | D19: =IF(F19=""," ",VLOOKUP(F19,'Project List 2026'!A:J,5,0)) -> Hana Kodatova | E19: Hana Kodatova | F19: BMC- Discovery Inventory PoC | G19: =IF(F19=""," ",VLOOKUP(F19,'Project List 2026'!A:J,6,0)) -> Internal | H19: =IF(F19="","",VLOOKUP(F19,'Project List 2026'!A:H,8,0)) -> 87002028 | J19: =IF(F19=""," ",VLOOKUP(F19,'Project List 2026'!A:O,15,0)) -> 130000 | K19: =IF(F19=""," ",VLOOKUP(F19,'Project List 2026'!A:T,9,0)) -> Ongoing | L19: =IF(F19=""," ",VLOOKUP(F19,'Project List 2026'!A:N,14,0)) -> 1 | M19: 0.3 | N19: 0.3 | O19: 0.3 | P19: 0.75 | Q19: 0.75 | R19: 0.4 | S19: 0.4 | Y19: =IF(ISNA(VLOOKUP(F19,'Project List 2026'!A:A,1,FALSE)), "No", "Yes") -> Yes
A20: =IF(F20=""," ",VLOOKUP(F20,'Project List 2026'!A:J,3,0)) -> Hosting | B20: =IF(F20=""," ",VLOOKUP(F20,'Project List 2026'!A:N,4,0)) -> IS - Other | C20: =IF(F20=""," ",VLOOKUP(E20,RefData!AG:AH,2,FALSE)) -> Infra Services | D20: =IF(F20=""," ",VLOOKUP(F20,'Project List 2026'!A:J,5,0)) -> Hana Kodatova | E20: Hana Kodatova | F20: Storage TR 2026 | G20: =IF(F20=""," ",VLOOKUP(F20,'Project List 2026'!A:J,6,0)) -> Internal | H20: =IF(F20="","",VLOOKUP(F20,'Project List 2026'!A:H,8,0)) -> 87101414 | J20: =IF(F20=""," ",VLOOKUP(F20,'Project List 2026'!A:O,15,0)) -> 238525 | K20: =IF(F20=""," ",VLOOKUP(F20,'Project List 2026'!A:T,9,0)) -> Ongoing | L20: =IF(F20=""," ",VLOOKUP(F20,'Project List 2026'!A:N,14,0)) -> 1 | N20: 0.3 | P20: 0.25 | Q20: 0.25 | R20: 0.15 | S20: 0.15 | T20: 0.15 | U20: 0.15 | Y20: =IF(ISNA(VLOOKUP(F20,'Project List 2026'!A:A,1,FALSE)), "No", "Yes") -> Yes
A21: =IF(F21=""," ",VLOOKUP(F21,'Project List 2026'!A:J,3,0)) -> Hosting | B21: =IF(F21=""," ",VLOOKUP(F21,'Project List 2026'!A:N,4,0)) -> Hosting Programs | C21: =IF(F21=""," ",VLOOKUP(E21,RefData!AG:AH,2,FALSE)) -> Infra Services | D21: =IF(F21=""," ",VLOOKUP(F21,'Project List 2026'!A:J,5,0)) -> Neeraja Duddu | E21: Hana Kodatova | F21: Dummy order - VACATIONS | G21: =IF(F21=""," ",VLOOKUP(F21,'Project List 2026'!A:J,6,0)) -> Internal | H21: =IF(F21="","",VLOOKUP(F21,'Project List 2026'!A:H,8,0)) -> n/a | J21: =IF(F21=""," ",VLOOKUP(F21,'Project List 2026'!A:O,15,0)) -> 0 | K21: =IF(F21=""," ",VLOOKUP(F21,'Project List 2026'!A:T,9,0)) -> Ongoing | L21: =IF(F21=""," ",VLOOKUP(F21,'Project List 2026'!A:N,14,0)) -> 1 | O21: 0.5 | T21: 0.25 | Y21: =IF(ISNA(VLOOKUP(F21,'Project List 2026'!A:A,1,FALSE)), "No", "Yes") -> Yes
A22: =IF(F22=""," ",VLOOKUP(F22,'Project List 2026'!A:J,3,0)) -> Hosting | B22: =IF(F22=""," ",VLOOKUP(F22,'Project List 2026'!A:N,4,0)) -> Hosting Programs | C22: =IF(F22=""," ",VLOOKUP(E22,RefData!AG:AH,2,FALSE)) -> Infra Services | D22: =IF(F22=""," ",VLOOKUP(F22,'Project List 2026'!A:J,5,0)) -> Hana Kodatova | E22: Hana Kodatova | F22: DSC FR - Infolog upgrade IT PM | G22: =IF(F22=""," ",VLOOKUP(F22,'Project List 2026'!A:J,6,0)) -> External | H22: =IF(F22="","",VLOOKUP(F22,'Project List 2026'!A:H,8,0)) -> 31318231 | J22: =IF(F22=""," ",VLOOKUP(F22,'Project List 2026'!A:O,15,0)) -> 4453 | K22: Ongoing | L22: =IF(F22=""," ",VLOOKUP(F22,'Project List 2026'!A:N,14,0)) -> 1 | M22: 0.2 | P22: 0.05 | Y22: =IF(ISNA(VLOOKUP(F22,'Project List 2026'!A:A,1,FALSE)), "No", "Yes") -> Yes
A23: =IF(F23=""," ",VLOOKUP(F23,'Project List 2026'!A:J,3,0)) -> Hosting | B23: =IF(F23=""," ",VLOOKUP(F23,'Project List 2026'!A:N,4,0)) -> Hosting Programs | C23: =IF(F23=""," ",VLOOKUP(E23,RefData!AG:AH,2,FALSE)) -> Infra Services | D23: =IF(F23=""," ",VLOOKUP(F23,'Project List 2026'!A:J,5,0)) -> Katerina Soukupova | E23: Hana Sinska | F23: SATs central PM order | G23: =IF(F23=""," ",VLOOKUP(F23,'Project List 2026'!A:J,6,0)) -> External | H23: =IF(F23="","",VLOOKUP(F23,'Project List 2026'!A:H,8,0)) -> 31319957 | J23: =IF(F23=""," ",VLOOKUP(F23,'Project List 2026'!A:O,15,0)) -> 474281 | K23: =IF(F23=""," ",VLOOKUP(F23,'Project List 2026'!A:T,9,0)) -> Ongoing | L23: =IF(F23=""," ",VLOOKUP(F23,'Project List 2026'!A:N,14,0)) -> 1 | M23: 0.5 | N23: 0.4 | O23: 0.4 | P23: 0.4 | Q23: 0.4 | R23: 0.4 | S23: 0.1 | T23: 0.25 | U23: 0.25 | V23: 0.25 | W23: 0.25 | X23: 0.5 | Y23: =IF(ISNA(VLOOKUP(F23,'Project List 2026'!A:A,1,FALSE)), "No", "Yes") -> Yes
A24: =IF(F24=""," ",VLOOKUP(F24,'Project List 2026'!A:J,3,0)) -> Hosting | B24: =IF(F24=""," ",VLOOKUP(F24,'Project List 2026'!A:N,4,0)) -> Hosting Programs | C24: =IF(F24=""," ",VLOOKUP(E24,RefData!AG:AH,2,FALSE)) -> Infra Services | D24: =IF(F24=""," ",VLOOKUP(F24,'Project List 2026'!A:J,5,0)) -> Neeraja Duddu | E24: Hana Sinska | F24: Dummy order - PART TIME | G24: =IF(F24=""," ",VLOOKUP(F24,'Project List 2026'!A:J,6,0)) -> Internal | H24: =IF(F24="","",VLOOKUP(F24,'Project List 2026'!A:H,8,0)) -> n/a | J24: =IF(F24=""," ",VLOOKUP(F24,'Project List 2026'!A:O,15,0)) -> 0 | K24: =IF(F24=""," ",VLOOKUP(F24,'Project List 2026'!A:T,9,0)) -> Ongoing | L24: =IF(F24=""," ",VLOOKUP(F24,'Project List 2026'!A:N,14,0)) -> 1 | M24: 0.2 | N24: 0.2 | O24: 0.2 | P24: 0.2 | Q24: 0.2 | R24: 0.2 | S24: 0.2 | T24: 0.2 | U24: 0.2 | V24: 0.2 | W24: 0.2 | X24: 0.2 | Y24: =IF(ISNA(VLOOKUP(F24,'Project List 2026'!A:A,1,FALSE)), "No", "Yes") -> Yes
A25: =IF(F25=""," ",VLOOKUP(F25,'Project List 2026'!A:J,3,0)) -> Hosting | B25: =IF(F25=""," ",VLOOKUP(F25,'Project List 2026'!A:N,4,0)) -> SEF | C25: Infra Services | D25: =IF(F25=""," ",VLOOKUP(F25,'Project List 2026'!A:J,5,0)) -> Hana Sinska | E25: Hana Sinska | F25: APIDOG | G25: =IF(F25=""," ",VLOOKUP(F25,'Project List 2026'!A:J,6,0)) -> Internal | H25: =IF(F25="","",VLOOKUP(F25,'Project List 2026'!A:H,8,0)) -> 87101388 | J25: =IF(F25=""," ",VLOOKUP(F25,'Project List 2026'!A:O,15,0)) -> 60000 | K25: =IF(F25=""," ",VLOOKUP(F25,'Project List 2026'!A:T,9,0)) -> Ongoing | L25: =IF(F25=""," ",VLOOKUP(F25,'Project List 2026'!A:N,14,0)) -> 1 | M25: 0.25 | N25: 0.15 | O25: 0.15 | P25: 0.1 | Q25: 0.1 | R25: 0.1 | Y25: Yes
A26: =IF(F26=""," ",VLOOKUP(F26,'Project List 2026'!A:J,3,0)) -> Hosting | B26: =IF(F26=""," ",VLOOKUP(F26,'Project List 2026'!A:N,4,0)) -> Hosting Programs | C26: =IF(F26=""," ",VLOOKUP(E26,RefData!AG:AH,2,FALSE)) -> Infra Services | D26: =IF(F26=""," ",VLOOKUP(F26,'Project List 2026'!A:J,5,0)) -> Hana Sinska | E26: Hana Sinska | F26: Dell Server Onboarding | G26: =IF(F26=""," ",VLOOKUP(F26,'Project List 2026'!A:J,6,0)) -> Internal | H26: =IF(F26="","",VLOOKUP(F26,'Project List 2026'!A:H,8,0)) -> 89101329 | J26: =IF(F26=""," ",VLOOKUP(F26,'Project List 2026'!A:O,15,0)) -> 251000 | K26: =IF(F26=""," ",VLOOKUP(F26,'Project List 2026'!A:T,9,0)) -> Ongoing | L26: =IF(F26=""," ",VLOOKUP(F26,'Project List 2026'!A:N,14,0)) -> 1 | M26: 0.25 | N26: 0.25 | O26: 0.25 | P26: 0.25 | Q26: 0.25 | R26: 0.25 | S26: 0.1 | T26: 0.25 | U26: 0.25 | V26: 0.25 | W26: 0.25 | Y26: Yes
A27: =IF(F27=""," ",VLOOKUP(F27,'Project List 2026'!A:J,3,0)) -> Hosting | B27: =IF(F27=""," ",VLOOKUP(F27,'Project List 2026'!A:N,4,0)) -> IS - Other | C27: =IF(F27=""," ",VLOOKUP(E27,RefData!AG:AH,2,FALSE)) -> Infra Services | D27: =IF(F27=""," ",VLOOKUP(F27,'Project List 2026'!A:J,5,0)) -> Hana Sinska | E27: Hana Sinska | F27: Internal servers EOL | G27: =IF(F27=""," ",VLOOKUP(F27,'Project List 2026'!A:J,6,0)) -> Internal | H27: =IF(F27="","",VLOOKUP(F27,'Project List 2026'!A:H,8,0)) -> 89101266 | J27: =IF(F27=""," ",VLOOKUP(F27,'Project List 2026'!A:O,15,0)) -> 13599.16 | K27: =IF(F27=""," ",VLOOKUP(F27,'Project List 2026'!A:T,9,0)) -> Ongoing | L27: =IF(F27=""," ",VLOOKUP(F27,'Project List 2026'!A:N,14,0)) -> 1 | N27: 0.15 | O27: 0.15 | P27: 0.15 | Q27: 0.15 | R27: 0.15 | S27: 0.05 | T27: 0.05 | U27: 0.05 | V27: 0.05 | W27: 0.05 | X27: 0.05 | Y27: Yes
A28: =IF(F28=""," ",VLOOKUP(F28,'Project List 2026'!A:J,3,0)) -> Hosting | B28: =IF(F28=""," ",VLOOKUP(F28,'Project List 2026'!A:N,4,0)) -> Hosting Programs | C28: =IF(F28=""," ",VLOOKUP(E28,RefData!AG:AH,2,FALSE)) -> Infra Services | D28: =IF(F28=""," ",VLOOKUP(F28,'Project List 2026'!A:J,5,0)) -> Katerina Soukupova | E28: Irina Denisova | F28: SATs central PM order | G28: =IF(F28=""," ",VLOOKUP(F28,'Project List 2026'!A:J,6,0)) -> External | H28: =IF(F28="","",VLOOKUP(F28,'Project List 2026'!A:H,8,0)) -> 31319957 | J28: =IF(F28=""," ",VLOOKUP(F28,'Project List 2026'!A:O,15,0)) -> 474281 | K28: =IF(F28=""," ",VLOOKUP(F28,'Project List 2026'!A:T,9,0)) -> Ongoing | L28: =IF(F28=""," ",VLOOKUP(F28,'Project List 2026'!A:N,14,0)) -> 1 | M28: 0.5 | N28: 0.5 | O28: 0.5 | P28: 0.5 | Q28: 0.5 | R28: 0.5 | S28: 0.4 | T28: 0.4 | U28: 0.4 | V28: 0.4 | W28: 0.4 | X28: 0.4 | Y28: =IF(ISNA(VLOOKUP(F28,'Project List 2026'!A:A,1,FALSE)), "No", "Yes") -> Yes
A29: =IF(F29=""," ",VLOOKUP(F29,'Project List 2026'!A:J,3,0)) -> Hosting | B29: =IF(F29=""," ",VLOOKUP(F29,'Project List 2026'!A:N,4,0)) -> Hosting Programs | C29: =IF(F29=""," ",VLOOKUP(E29,RefData!AG:AH,2,FALSE)) -> Infra Services | D29: =IF(F29=""," ",VLOOKUP(F29,'Project List 2026'!A:J,5,0)) -> Jana Veberova | E29: Irina Denisova | F29: EXP EU Ws2016 OS R. - Server Refresh | G29: =IF(F29=""," ",VLOOKUP(F29,'Project List 2026'!A:J,6,0)) -> External | H29: =IF(F29="","",VLOOKUP(F29,'Project List 2026'!A:H,8,0)) -> 31319332 | J29: =IF(F29=""," ",VLOOKUP(F29,'Project List 2026'!A:O,15,0)) -> 321571.2 | K29: =IF(F29=""," ",VLOOKUP(F29,'Project List 2026'!A:T,9,0)) -> Ongoing | L29: =IF(F29=""," ",VLOOKUP(F29,'Project List 2026'!A:N,14,0)) -> 1 | M29: 0.5 | N29: 0.5 | O29: 0.5 | P29: 0.5 | Q29: 0.5 | R29: 0.5 | S29: 0.4 | T29: 0.4 | U29: 0.4 | V29: 0.4 | W29: 0.4 | X29: 0.4 | Y29: =IF(ISNA(VLOOKUP(F29,'Project List 2026'!A:A,1,FALSE)), "No", "Yes") -> Yes
A30: =IF(F30=""," ",VLOOKUP(F30,'Project List 2026'!A:J,3,0)) -> Hosting | B30: =IF(F30=""," ",VLOOKUP(F30,'Project List 2026'!A:N,4,0)) -> IS - Other | C30: =IF(F30=""," ",VLOOKUP(E30,RefData!AG:AH,2,FALSE)) -> Infra Services | D30: =IF(F30=""," ",VLOOKUP(F30,'Project List 2026'!A:J,5,0)) -> Ivan Godunov | E30: Ivan Godunov | F30: PoC - BMC - OpenShift onboarding | G30: =IF(F30=""," ",VLOOKUP(F30,'Project List 2026'!A:J,6,0)) -> Internal | H30: =IF(F30="","",VLOOKUP(F30,'Project List 2026'!A:H,8,0)) -> 87002011 | J30: =IF(F30=""," ",VLOOKUP(F30,'Project List 2026'!A:O,15,0)) -> 24830 | K30: =IF(F30=""," ",VLOOKUP(F30,'Project List 2026'!A:T,9,0)) -> Completed | L30: =IF(F30=""," ",VLOOKUP(F30,'Project List 2026'!A:N,14,0)) -> 1 | M30: 0.5 | N30: 0.3 | O30: 0.3 | P30: 0.3 | Q30: 0.05 | R30: 0.05 | Y30: =IF(ISNA(VLOOKUP(F30,'Project List 2026'!A:A,1,FALSE)), "No", "Yes") -> Yes
A31: =IF(F31=""," ",VLOOKUP(F31,'Project List 2026'!A:J,3,0)) -> Hosting | B31: =IF(F31=""," ",VLOOKUP(F31,'Project List 2026'!A:N,4,0)) -> IS - Other | C31: =IF(F31=""," ",VLOOKUP(E31,RefData!AG:AH,2,FALSE)) -> Infra Services | D31: =IF(F31=""," ",VLOOKUP(F31,'Project List 2026'!A:J,5,0)) -> Ivan Godunov | E31: Ivan Godunov | F31: Malware servers scanning | G31: =IF(F31=""," ",VLOOKUP(F31,'Project List 2026'!A:J,6,0)) -> Internal | H31: =IF(F31="","",VLOOKUP(F31,'Project List 2026'!A:H,8,0)) -> 89101198 | J31: =IF(F31=""," ",VLOOKUP(F31,'Project List 2026'!A:O,15,0)) -> 0 | K31: =IF(F31=""," ",VLOOKUP(F31,'Project List 2026'!A:T,9,0)) -> Ongoing | L31: =IF(F31=""," ",VLOOKUP(F31,'Project List 2026'!A:N,14,0)) -> 1 | N31: 0.4 | O31: 0.4 | Y31: =IF(ISNA(VLOOKUP(F31,'Project List 2026'!A:A,1,FALSE)), "No", "Yes") -> Yes
A32: =IF(F32=""," ",VLOOKUP(F32,'Project List 2026'!A:J,3,0)) -> Hosting | B32: =IF(F32=""," ",VLOOKUP(F32,'Project List 2026'!A:N,4,0)) -> Hosting Programs | C32: Infra Services | D32: =IF(F32=""," ",VLOOKUP(F32,'Project List 2026'!A:J,5,0)) -> Zlata Benesova | E32: Ivan Godunov | F32: DeC GHO EVRi IT_29 Transition 2026 | G32: =IF(F32=""," ",VLOOKUP(F32,'Project List 2026'!A:J,6,0)) -> External | H32: =IF(F32="","",VLOOKUP(F32,'Project List 2026'!A:H,8,0)) -> 31319843 | J32: =IF(F32=""," ",VLOOKUP(F32,'Project List 2026'!A:O,15,0)) -> 1355572 | K32: =IF(F32=""," ",VLOOKUP(F32,'Project List 2026'!A:T,9,0)) -> Ongoing | L32: =IF(F32=""," ",VLOOKUP(F32,'Project List 2026'!A:N,14,0)) -> 1 | N32: 0.3 | O32: 0.3 | Y32: =IF(ISNA(VLOOKUP(F32,'Project List 2026'!A:A,1,FALSE)), "No", "Yes") -> Yes
A33: =IF(F33=""," ",VLOOKUP(F33,'Project List 2026'!A:J,3,0)) -> Hosting | B33: =IF(F33=""," ",VLOOKUP(F33,'Project List 2026'!A:N,4,0)) -> IS - Other | C33: =IF(F33=""," ",VLOOKUP(E33,RefData!AG:AH,2,FALSE)) -> Infra Services | D33: =IF(F33=""," ",VLOOKUP(F33,'Project List 2026'!A:J,5,0)) -> Ivan Godunov | E33: Ivan Godunov | F33: ITS resilient operations | G33: =IF(F33=""," ",VLOOKUP(F33,'Project List 2026'!A:J,6,0)) -> Internal | H33: =IF(F33="","",VLOOKUP(F33,'Project List 2026'!A:H,8,0)) -> 87002052 | J33: =IF(F33=""," ",VLOOKUP(F33,'Project List 2026'!A:O,15,0)) -> 151060 | K33: =IF(F33=""," ",VLOOKUP(F33,'Project List 2026'!A:T,9,0)) -> Ongoing | L33: =IF(F33=""," ",VLOOKUP(F33,'Project List 2026'!A:N,14,0)) -> 1 | M33: 0.5 | N33: 0.3 | O33: 0.3 | P33: 0.8 | Q33: 0.9 | R33: 0.9 | S33: 0.9 | T33: 0.9 | U33: 0.9 | V33: 0.9 | W33: 0.9 | X33: 0.9 | Y33: =IF(ISNA(VLOOKUP(F33,'Project List 2026'!A:A,1,FALSE)), "No", "Yes") -> Yes
A34: =IF(F34=""," ",VLOOKUP(F34,'Project List 2026'!A:J,3,0)) -> Telecoms | B34: =IF(F34=""," ",VLOOKUP(F34,'Project List 2026'!A:N,4,0)) -> Telecoms | C34: =IF(F34=""," ",VLOOKUP(E34,RefData!AG:AH,2,FALSE)) -> Telecoms | D34: =IF(F34=""," ",VLOOKUP(F34,'Project List 2026'!A:J,5,0)) -> Jan Cesnek | E34: Jan Cesnek | F34: New NGFW requests | G34: =IF(F34=""," ",VLOOKUP(F34,'Project List 2026'!A:J,6,0)) -> External | H34: =IF(F34="","",VLOOKUP(F34,'Project List 2026'!A:H,8,0)) -> Multiple | J34: =IF(F34=""," ",VLOOKUP(F34,'Project List 2026'!A:O,15,0)) -> 500000 | K34: =IF(F34=""," ",VLOOKUP(F34,'Project List 2026'!A:T,9,0)) -> Ongoing | L34: =IF(F34=""," ",VLOOKUP(F34,'Project List 2026'!A:N,14,0)) -> 1 | M34: 1 | N34: 1 | O34: 1 | P34: 1 | Q34: 1 | R34: 1 | S34: 1 | T34: 1 | U34: 1 | V34: 1 | W34: 1 | X34: 1 | Y34: =IF(ISNA(VLOOKUP(F34,'Project List 2026'!A:A,1,FALSE)), "No", "Yes") -> Yes
